Workbook

Sheet KAPASİTE TABLOSU
A1: İL ADI | B1: İLÇE ADI | C1: YURDUN ADI | D1: KAPANIŞ TARİHİ | E1: AÇIK KALACAK YURT | H1: AÇIKLAMA
E2: KIZ ÖĞRENCİLER | G2: ERKEK ÖĞRENCİLER
A3: ADANA | B3: MERKEZ | C3: ADANA ÖĞRENCİ YURDU | D3: 42552 | E3: X | G3: A BLOK AÇIK
A4: ADANA | B4: MERKEZ | C4: FEVZİ ÇAKMAK YURDU(ADANA) | D4: 42552 | E4: X | G4: X
A5: ADANA | B5: MERKEZ | C5: HACI SABANCI YURDU(ADANA) | D5: 42552 | E5: X | G5: X
A6: ADANA | B6: MERKEZ | C6: SÜMER YURDU | D6: 42552 | E6: X | G6: X
A7: ADANA | B7: MERKEZ | C7: MAHMUT SAMİ RAMAZANOĞLU ÖĞRENCİ YURDU | D7: 42552 | E7: A BLOK AÇIK | G7: X
A8: ADANA | B8: CEYHAN | C8: CEYHAN YURDU | D8: 42566 | E8: X | G8: X
A9: ADIYAMAN | B9: MERKEZ | C9: ADIYAMAN YURDU | D9: 42548 | E9: D BLOK AÇIK | G9: X
A10: ADIYAMAN | B10: MERKEZ | C10: VEYSEL KARANİ YURDU | D10: 42548 | E10: X | G10: B BLOK AÇIK
A11: ADIYAMAN | B11: MERKEZ | C11: SAFVAN BİN MUATTAL YURDU | D11: 42548 | E11: X | G11: X
A12: ADIYAMAN | B12: BESNİ | C12: BESNİ- SERVİ M.ERDEMOĞLU YURDU | D12: 42548 | E12: X | G12: X
A13: ADIYAMAN | B13: KAHTA | C13: KAHTA YURDU | D13: 42548 | E13: X | G13: X
A14: AFYONKARAHİSAR | B14: MERKEZ | C14: AFYON YURDU | D14: 42548 | E14: X | G14: X
... A49: ANKARA | B49: MERKEZ | C49: EYMİR ERKEK ÖĞRENCİ YURDU | D49: 42551 | E49: X | G49: X
A50: ANKARA | B50: MERKEZ | C50: EMİNE ŞERİFE HANIM ÖĞRENCİ YURDU | D50: 42551 | E50: AÇIK | G50: X | H50: Öğrenciler, misafirler ve KKK misafirleri
A51: ANKARA | B51: MERKEZ | C51: GAZİ YURDU | D51: 42551 | E51: X | G51: X
A52: ANKARA | B52: MERKEZ | C52: GÖLBAŞI KIZ ÖĞRENCİ YURDU | D52: 42551 | E52: AÇIK | G52: X | H52: Misafir Gruplar için açık
A53: ANKARA | B53: MERKEZ | C53: GÜVENLİK YURDU | D53: 42551 | E53: X | G53: X
A54: ANKARA | B54: MERKEZ | C54: ANKARA HACI BAYRAM-I VELİ ÖĞRENCİ YURDU | D54: 42551 | E54: X | G54: AÇIK
A55: ANKARA | B55: MERKEZ | C55: HACI ÖMER SABANCI YURDU(ANKARA) | D55: 42551 | E55: X | G55: X
A56: ANKARA | B56: MERKEZ | C56: HALİDE EDİP ADIVAR YURDU | D56: 42551 | E56: X | G56: X
A57: ANKARA | B57: MERKEZ | C57: KOCATEPE YURDU | D57: 42551 | E57: X | G57: X
A58: ANKARA | B58: MERKEZ | C58: MAHMUT NEDİM ZAPÇI YURDU(ANK) | D58: 42551 | E58: X | G58: X
A59: ANKARA | B59: MERKEZ | C59: MEHMET AKİF YURDU (ANKARA) | D59: 42551 | E59: X | G59: X
A60: ANKARA | B60: MERKEZ | C60: NENEHATUN YURDU | D60: 42551 | E60: X | G60: X
A61: ANKARA | B61: MERKEZ | C61: SEYRAN YURDU | D61: 42551 | E61: X | G61: X
A62: ANKARA | B62: MERKEZ | C62: ŞERİFE BACI YURDU | D62: 42551 | E62: X | G62: X
A63: ANKARA | B63: MERKEZ | C63: TAHSİN BANGUOĞLU YURDU | D63: 42545 | E63: X | G63: AÇIK | H63: Öğrenciler, misafirler ve KKK misafirleri
A64: ANKARA | B64: MERKEZ | C64: YENİŞEHİR YURDU | D64: 42551 | E64: X | G64: X
A65: ANKARA | B65: MERKEZ | C65: YUNUS EMRE YURDU | D65: 42551 | E65: X | G65: AÇIK
A66: ANKARA | B66: MERKEZ | C66: ZÜBEYDE HANIM YURDU(ANKARA) | D66: 42551 | E66: X | G66: X
A67: ANKARA | B67: ÇUBUK | C67: ÇUBUK ULUBEY ÖĞRENCİ YURDU | D67: 42551 | E67: X | G67: X
A68: ANKARA | B68: ÇUBUK | C68: FATMA HANIM ÖĞRENCİ YURDU | D68: 42551 | E68: X | G68: X
A69: ANKARA | B69: KALECİK | C69: KALECİK YURDU | D69: 42547 | E69: 1. KAT AÇIK | G69: X
A70: ANKARA | B70: POLATLI | C70: POLATLI YURDU | D70: 42551 | E70: X | G70: X
A71: ANKARA | B71: ŞEREFLİKOÇHİSAR | C71: ŞEREFLİKOÇHİSAR YURDU | D71: 42565 | E71: X | G71: X
A72: ANKARA | B72: NALLIHAN | C72: ALİ SEMERKANDİ ÖĞRENCİ YURDU | D72: 42545 | E72: X | G72: X
A73: ANTALYA | B73: MERKEZ | C73: AKDENİZ YURDU | D73: 42552 | E73: X | G73: X
A74: ANTALYA | B74: MERKEZ | C74: BEZM-İ ALEM VALİDE SULTAN ÖĞRENCİ YURDU | D74: 42552 | E74: AÇIK | G74: X
...

Sheet İL-İLÇE BAZINDA KAPASİTE
A1: İL/İLÇE | B1: YURT SAYISI | C1: KAPASİTE | G1: İL | H1: İLÇE
C2: KIZ | D2: ERKEK | E2: TOPLAM
A3: ADANA/ADANA | B3: =COUNTIF('KAPASİTE TABLOSU'!F:F,'İL-İLÇE BAZINDA KAPASİTE'!A3) -> 0 | C3: =SUMIF('KAPASİTE TABLOSU'!$F:$F,'İL-İLÇE BAZINDA KAPASİTE'!$A3,'KAPASİTE TABLOSU'!#REF!) -> #REF! | D3: =SUMIF('KAPASİTE TABLOSU'!$F:$F,'İL-İLÇE BAZINDA KAPASİTE'!$A3,'KAPASİTE TABLOSU'!#REF!) -> #REF! | E3: =SUMIF('KAPASİTE TABLOSU'!$F:$F,'İL-İLÇE BAZINDA KAPASİTE'!$A3,'KAPASİTE TABLOSU'!#REF!) -> #REF! | F3: =IF(G3=H3,"İL","İLÇE") -> İL | G3: ADANA | H3: ADANA
A4: ADANA/CEYHAN | B4: =COUNTIF('KAPASİTE TABLOSU'!F:F,'İL-İLÇE BAZINDA KAPASİTE'!A4) -> 0 | C4: =SUMIF('KAPASİTE TABLOSU'!$F:$F,'İL-İLÇE BAZINDA KAPASİTE'!$A4,'KAPASİTE TABLOSU'!#REF!) -> #REF! | D4: =SUMIF('KAPASİTE TABLOSU'!$F:$F,'İL-İLÇE BAZINDA KAPASİTE'!$A4,'KAPASİTE TABLOSU'!#REF!) -> #REF! | E4: =SUMIF('KAPASİTE TABLOSU'!$F:$F,'İL-İLÇE BAZINDA KAPASİTE'!$A4,'KAPASİTE TABLOSU'!#REF!) -> #REF! | F4: =IF(G4=H4,"İL","İLÇE") -> İLÇE | G4: ADANA | H4: CEYHAN
A5: ADANA/KOZAN | B5: =COUNTIF('KAPASİTE TABLOSU'!F:F,'İL-İLÇE BAZINDA KAPASİTE'!A5) -> 0 | C5: =SUMIF('KAPASİTE TABLOSU'!$F:$F,'İL-İLÇE BAZINDA KAPASİTE'!$A5,'KAPASİTE TABLOSU'!#REF!) -> #REF! | D5: =SUMIF('KAPASİTE TABLOSU'!$F:$F,'İL-İLÇE BAZINDA KAPASİTE'!$A5,'KAPASİTE TABLOSU'!#REF!) -> #REF! | E5: =SUMIF('KAPASİTE TABLOSU'!$F:$F,'İL-İLÇE BAZINDA KAPASİTE'!$A5,'KAPASİTE TABLOSU'!#REF!) -> #REF! | F5: =IF(G5=H5,"İL","İLÇE") -> İLÇE | G5: ADANA | H5: CEYHAN
A6: ADIYAMAN/ADIYAMAN | B6: =COUNTIF('KAPASİTE TABLOSU'!F:F,'İL-İLÇE BAZINDA KAPASİTE'!A6) -> 0 | C6: =SUMIF('KAPASİTE TABLOSU'!$F:$F,'İL-İLÇE BAZINDA KAPASİTE'!$A6,'KAPASİTE TABLOSU'!#REF!) -> #REF! | D6: =SUMIF('KAPASİTE TABLOSU'!$F:$F,'İL-İLÇE BAZINDA KAPASİTE'!$A6,'KAPASİTE TABLOSU'!#REF!) -> #REF! | E6: =SUMIF('KAPASİTE TABLOSU'!$F:$F,'İL-İLÇE BAZINDA KAPASİTE'!$A6,'KAPASİTE TABLOSU'!#REF!) -> #REF! | F6: =IF(G6=H6,"İL","İLÇE") -> İL | G6: ADIYAMAN | H6: ADIYAMAN
A7: ADIYAMAN/BESNİ | B7: =COUNTIF('KAPASİTE TABLOSU'!F:F,'İL-İLÇE BAZINDA KAPASİTE'!A7) -> 0 | C7: =SUMIF('KAPASİTE TABLOSU'!$F:$F,'İL-İLÇE BAZINDA KAPASİTE'!$A7,'KAPASİTE TABLOSU'!#REF!) -> #REF! | D7: =SUMIF('KAPASİTE TABLOSU'!$F:$F,'İL-İLÇE BAZINDA KAPASİTE'!$A7,'KAPASİTE TABLOSU'!#REF!) -> #REF! | E7: =SUMIF('KAPASİTE TABLOSU'!$F:$F,'İL-İLÇE BAZINDA KAPASİTE'!$A7,'KAPASİTE TABLOSU'!#REF!) -> #REF! | F7: =IF(G7=H7,"İL","İLÇE") -> İLÇE | G7: ADIYAMAN | H7: BESNİ
A8: ADIYAMAN/KAHTA | B8: =COUNTIF('KAPASİTE TABLOSU'!F:F,'İL-İLÇE BAZINDA KAPASİTE'!A8) -> 0 | C8: =SUMIF('KAPASİTE TABLOSU'!$F:$F,'İL-İLÇE BAZINDA KAPASİTE'!$A8,'KAPASİTE TABLOSU'!#REF!) -> #REF! | D8: =SUMIF('KAPASİTE TABLOSU'!$F:$F,'İL-İLÇE BAZINDA KAPASİTE'!$A8,'KAPASİTE TABLOSU'!#REF!) -> #REF! | E8: =SUMIF('KAPASİTE TABLOSU'!$F:$F,'İL-İLÇE BAZINDA KAPASİTE'!$A8,'KAPASİTE TABLOSU'!#REF!) -> #REF! | F8: =IF(G8=H8,"İL","İLÇE") -> İLÇE | G8: ADIYAMAN | H8: KAHTA
A9: AFYONKARAHİSAR/AFYONKARAHİSAR | B9: =COUNTIF('KAPASİTE TABLOSU'!F:F,'İL-İLÇE BAZINDA KAPASİTE'!A9) -> 0 | C9: =SUMIF('KAPASİTE TABLOSU'!$F:$F,'İL-İLÇE BAZINDA KAPASİTE'!$A9,'KAPASİTE TABLOSU'!#REF!) -> #REF! | D9: =SUMIF('KAPASİTE TABLOSU'!$F:$F,'İL-İLÇE BAZINDA KAPASİTE'!$A9,'KAPASİTE TABLOSU'!#REF!) -> #REF! | E9: =SUMIF('KAPASİTE TABLOSU'!$F:$F,'İL-İLÇE BAZINDA KAPASİTE'!$A9,'KAPASİTE TABLOSU'!#REF!) -> #REF! | F9: =IF(G9=H9,"İL","İLÇE") -> İL | G9: AFYONKARAHİSAR | H9: AFYONKARAHİSAR
A10: AFYONKARAHİSAR/SANDIKLI | B10: =COUNTIF('KAPASİTE TABLOSU'!F:F,'İL-İLÇE BAZINDA KAPASİTE'!A10) -> 0 | C10: =SUMIF('KAPASİTE TABLOSU'!$F:$F,'İL-İLÇE BAZINDA KAPASİTE'!$A10,'KAPASİTE TABLOSU'!#REF!) -> #REF! | D10: =SUMIF('KAPASİTE TABLOSU'!$F:$F,'İL-İLÇE BAZINDA KAPASİTE'!$A10,'KAPASİTE TABLOSU'!#REF!) -> #REF! | E10: =SUMIF('KAPASİTE TABLOSU'!$F:$F,'İL-İLÇE BAZINDA KAPASİTE'!$A10,'KAPASİTE TABLOSU'!#REF!) -> #REF! | F10: =IF(G10=H10,"İL","İLÇE") -> İLÇE | G10: AFYONKARAHİSAR | H10: SANDIKLI
A11: AFYONKARAHİSAR/BAYAT | B11: =COUNTIF('KAPASİTE TABLOSU'!F:F,'İL-İLÇE BAZINDA KAPASİTE'!A11) -> 0 | C11: =SUMIF('KAPASİTE TABLOSU'!$F:$F,'İL-İLÇE BAZINDA KAPASİTE'!$A11,'KAPASİTE TABLOSU'!#REF!) -> #REF! | D11: =SUMIF('KAPASİTE TABLOSU'!$F:$F,'İL-İLÇE BAZINDA KAPASİTE'!$A11,'KAPASİTE TABLOSU'!#REF!) -> #REF! | E11: =SUMIF('KAPASİTE TABLOSU'!$F:$F,'İL-İLÇE BAZINDA KAPASİTE'!$A11,'KAPASİTE TABLOSU'!#REF!) -> #REF! | F11: =IF(G11=H11,"İL","İLÇE") -> İLÇE | G11: AFYONKARAHİSAR | H11: BAYAT
A12: AFYONKARAHİSAR/DİNAR | B12: =COUNTIF('KAPASİTE TABLOSU'!F:F,'İL-İLÇE BAZINDA KAPASİTE'!A12) -> 0 | C12: =SUMIF('KAPASİTE TABLOSU'!$F:$F,'İL-İLÇE BAZINDA KAPASİTE'!$A12,'KAPASİTE TABLOSU'!#REF!) -> #REF! | D12: =SUMIF('KAPASİTE TABLOSU'!$F:$F,'İL-İLÇE BAZINDA KAPASİTE'!$A12,'KAPASİTE TABLOSU'!#REF!) -> #REF! | E12: =SUMIF('KAPASİTE TABLOSU'!$F:$F,'İL-İLÇE BAZINDA KAPASİTE'!$A12,'KAPASİTE TABLOSU'!#REF!) -> #REF! | F12: =IF(G12=H12,"İL","İLÇE") -> İLÇE | G12: AFYONKARAHİSAR | H12: DİNAR
A13: AFYONKARAHİSAR/EMİRDAĞ | B13: =COUNTIF('KAPASİTE TABLOSU'!F:F,'İL-İLÇE BAZINDA KAPASİTE'!A13) -> 0 | C13: =SUMIF('KAPASİTE TABLOSU'!$F:$F,'İL-İLÇE BAZINDA KAPASİTE'!$A13,'KAPASİTE TABLOSU'!#REF!) -> #REF! | D13: =SUMIF('KAPASİTE TABLOSU'!$F:$F,'İL-İLÇE BAZINDA KAPASİTE'!$A13,'KAPASİTE TABLOSU'!#REF!) -> #REF! | E13: =SUMIF('KAPASİTE TABLOSU'!$F:$F,'İL-İLÇE BAZINDA KAPASİTE'!$A13,'KAPASİTE TABLOSU'!#REF!) -> #REF! | F13: =IF(G13=H13,"İL","İLÇE") -> İLÇE | G13: AFYONKARAHİSAR | H13: EMİRDAĞ
A14: AFYONKARAHİSAR/ŞUHUT | B14: =COUNTIF('KAPASİTE TABLOSU'!F:F,'İL-İLÇE BAZINDA KAPASİTE'!A14) -> 0 | C14: =SUMIF('KAPASİTE TABLOSU'!$F:$F,'İL-İLÇE BAZINDA KAPASİTE'!$A14,'KAPASİTE TABLOSU'!#REF!) -> #REF! | D14: =SUMIF('KAPASİTE TABLOSU'!$F:$F,'İL-İLÇE BAZINDA KAPASİTE'!$A14,'KAPASİTE TABLOSU'!#REF!) -> #REF! | E14: =SUMIF('KAPASİTE TABLOSU'!$F:$F,'İL-İLÇE BAZINDA KAPASİTE'!$A14,'KAPASİTE TABLOSU'!#REF!) -> #REF! | F14: =IF(G14=H14,"İL","İLÇE") -> İLÇE | G14: AFYONKARAHİSAR | H14: ŞUHUT
... A133: KARS/KARS | B133: =COUNTIF('KAPASİTE TABLOSU'!F:F,'İL-İLÇE BAZINDA KAPASİTE'!A133) -> 0 | C133: =SUMIF('KAPASİTE TABLOSU'!$F:$F,'İL-İLÇE BAZINDA KAPASİTE'!$A133,'KAPASİTE TABLOSU'!#REF!) -> #REF! | D133: =SUMIF('KAPASİTE TABLOSU'!$F:$F,'İL-İLÇE BAZINDA KAPASİTE'!$A133,'KAPASİTE TABLOSU'!#REF!) -> #REF! | E133: =SUMIF('KAPASİTE TABLOSU'!$F:$F,'İL-İLÇE BAZINDA KAPASİTE'!$A133,'KAPASİTE TABLOSU'!#REF!) -> #REF! | F133: =IF(G133=H133,"İL","İLÇE") -> İL | G133: KARS | H133: KARS
A134: KARS/SARIKAMIŞ | B134: 1 | C134: =SUMIF('KAPASİTE TABLOSU'!$F:$F,'İL-İLÇE BAZINDA KAPASİTE'!$A134,'KAPASİTE TABLOSU'!#REF!) -> #REF! | D134: =SUMIF('KAPASİTE TABLOSU'!$F:$F,'İL-İLÇE BAZINDA KAPASİTE'!$A134,'KAPASİTE TABLOSU'!#REF!) -> #REF! | E134: =SUMIF('KAPASİTE TABLOSU'!$F:$F,'İL-İLÇE BAZINDA KAPASİTE'!$A134,'KAPASİTE TABLOSU'!#REF!) -> #REF! | F134: =IF(G134=H134,"İL","İLÇE") -> İLÇE | G134: KARS | H134: SARIKAMIŞ
A135: KASTAMONU/KASTAMONU | B135: =COUNTIF('KAPASİTE TABLOSU'!F:F,'İL-İLÇE BAZINDA KAPASİTE'!A135) -> 0 | C135: =SUMIF('KAPASİTE TABLOSU'!$F:$F,'İL-İLÇE BAZINDA KAPASİTE'!$A135,'KAPASİTE TABLOSU'!#REF!) -> #REF! | D135: =SUMIF('KAPASİTE TABLOSU'!$F:$F,'İL-İLÇE BAZINDA KAPASİTE'!$A135,'KAPASİTE TABLOSU'!#REF!) -> #REF! | E135: =SUMIF('KAPASİTE TABLOSU'!$F:$F,'İL-İLÇE BAZINDA KAPASİTE'!$A135,'KAPASİTE TABLOSU'!#REF!) -> #REF! | F135: =IF(G135=H135,"İL","İLÇE") -> İL | G135: KASTAMONU | H135: KASTAMONU
A136: KAYSERİ/KAYSERİ | B136: =COUNTIF('KAPASİTE TABLOSU'!F:F,'İL-İLÇE BAZINDA KAPASİTE'!A136) -> 0 | C136: =SUMIF('KAPASİTE TABLOSU'!$F:$F,'İL-İLÇE BAZINDA KAPASİTE'!$A136,'KAPASİTE TABLOSU'!#REF!) -> #REF! | D136: =SUMIF('KAPASİTE TABLOSU'!$F:$F,'İL-İLÇE BAZINDA KAPASİTE'!$A136,'KAPASİTE TABLOSU'!#REF!) -> #REF! | E136: =SUMIF('KAPASİTE TABLOSU'!$F:$F,'İL-İLÇE BAZINDA KAPASİTE'!$A136,'KAPASİTE TABLOSU'!#REF!) -> #REF! | F136: =IF(G136=H136,"İL","İLÇE") -> İL | G136: KAYSERİ | H136: KAYSERİ
A137: KAYSERİ/DEVELİ | B137: =COUNTIF('KAPASİTE TABLOSU'!F:F,'İL-İLÇE BAZINDA KAPASİTE'!A137) -> 0 | C137: =SUMIF('KAPASİTE TABLOSU'!$F:$F,'İL-İLÇE BAZINDA KAPASİTE'!$A137,'KAPASİTE TABLOSU'!#REF!) -> #REF! | D137: =SUMIF('KAPASİTE TABLOSU'!$F:$F,'İL-İLÇE BAZINDA KAPASİTE'!$A137,'KAPASİTE TABLOSU'!#REF!) -> #REF! | E137: =SUMIF('KAPASİTE TABLOSU'!$F:$F,'İL-İLÇE BAZINDA KAPASİTE'!$A137,'KAPASİTE TABLOSU'!#REF!) -> #REF! | F137: =IF(G137=H137,"İL","İLÇE") -> İLÇE | G137: KAYSERİ | H137: DEVELİ
A138: KAYSERİ/PINARBAŞI | B138: =COUNTIF('KAPASİTE TABLOSU'!F:F,'İL-İLÇE BAZINDA KAPASİTE'!A138) -> 0 | C138: =SUMIF('KAPASİTE TABLOSU'!$F:$F,'İL-İLÇE BAZINDA KAPASİTE'!$A138,'KAPASİTE TABLOSU'!#REF!) -> #REF! | D138: =SUMIF('KAPASİTE TABLOSU'!$F:$F,'İL-İLÇE BAZINDA KAPASİTE'!$A138,'KAPASİTE TABLOSU'!#REF!) -> #REF! | E138: =SUMIF('KAPASİTE TABLOSU'!$F:$F,'İL-İLÇE BAZINDA KAPASİTE'!$A138,'KAPASİTE TABLOSU'!#REF!) -> #REF! | F138: =IF(G138=H138,"İL","İLÇE") -> İLÇE | G138: KAYSERİ | H138: PINARBAŞI
A139: KIRIKKALE/KIRIKKALE | B139: =COUNTIF('KAPASİTE TABLOSU'!F:F,'İL-İLÇE BAZINDA KAPASİTE'!A139) -> 0 | C139: =SUMIF('KAPASİTE TABLOSU'!$F:$F,'İL-İLÇE BAZINDA KAPASİTE'!$A139,'KAPASİTE TABLOSU'!#REF!) -> #REF! | D139: =SUMIF('KAPASİTE TABLOSU'!$F:$F,'İL-İLÇE BAZINDA KAPASİTE'!$A139,'KAPASİTE TABLOSU'!#REF!) -> #REF! | E139: =SUMIF('KAPASİTE TABLOSU'!$F:$F,'İL-İLÇE BAZINDA KAPASİTE'!$A139,'KAPASİTE TABLOSU'!#REF!) -> #REF! | F139: =IF(G139=H139,"İL","İLÇE") -> İL | G139: KIRIKKALE | H139: KIRIKKALE
A140: KIRIKKALE/KESKİN | B140: =COUNTIF('KAPASİTE TABLOSU'!F:F,'İL-İLÇE BAZINDA KAPASİTE'!A140) -> 0 | C140: =SUMIF('KAPASİTE TABLOSU'!$F:$F,'İL-İLÇE BAZINDA KAPASİTE'!$A140,'KAPASİTE TABLOSU'!#REF!) -> #REF! | D140: =SUMIF('KAPASİTE TABLOSU'!$F:$F,'İL-İLÇE BAZINDA KAPASİTE'!$A140,'KAPASİTE TABLOSU'!#REF!) -> #REF! | E140: =SUMIF('KAPASİTE TABLOSU'!$F:$F,'İL-İLÇE BAZINDA KAPASİTE'!$A140,'KAPASİTE TABLOSU'!#REF!) -> #REF! | F140: =IF(G140=H140,"İL","İLÇE") -> İLÇE | G140: KIRIKKALE | H140: KESKİN
A141: KIRKLARELİ/KIRKLARELİ | B141: =COUNTIF('KAPASİTE TABLOSU'!F:F,'İL-İLÇE BAZINDA KAPASİTE'!A141) -> 0 | C141: =SUMIF('KAPASİTE TABLOSU'!$F:$F,'İL-İLÇE BAZINDA KAPASİTE'!$A141,'KAPASİTE TABLOSU'!#REF!) -> #REF! | D141: =SUMIF('KAPASİTE TABLOSU'!$F:$F,'İL-İLÇE BAZINDA KAPASİTE'!$A141,'KAPASİTE TABLOSU'!#REF!) -> #REF! | E141: =SUMIF('KAPASİTE TABLOSU'!$F:$F,'İL-İLÇE BAZINDA KAPASİTE'!$A141,'KAPASİTE TABLOSU'!#REF!) -> #REF! | F141: =IF(G141=H141,"İL","İLÇE") -> İL | G141: KIRKLARELİ | H141: KIRKLARELİ
A142: KIRKLARELİ/LÜLEBURGAZ | B142: =COUNTIF('KAPASİTE TABLOSU'!F:F,'İL-İLÇE BAZINDA KAPASİTE'!A142) -> 0 | C142: =SUMIF('KAPASİTE TABLOSU'!$F:$F,'İL-İLÇE BAZINDA KAPASİTE'!$A142,'KAPASİTE TABLOSU'!#REF!) -> #REF! | D142: =SUMIF('KAPASİTE TABLOSU'!$F:$F,'İL-İLÇE BAZINDA KAPASİTE'!$A142,'KAPASİTE TABLOSU'!#REF!) -> #REF! | E142: =SUMIF('KAPASİTE TABLOSU'!$F:$F,'İL-İLÇE BAZINDA KAPASİTE'!$A142,'KAPASİTE TABLOSU'!#REF!) -> #REF! | F142: =IF(G142=H142,"İL","İLÇE") -> İLÇE | G142: KIRKLARELİ | H142: LÜLEBURGAZ
A143: KIRŞEHİR/KIRŞEHİR | B143: =COUNTIF('KAPASİTE TABLOSU'!F:F,'İL-İLÇE BAZINDA KAPASİTE'!A143) -> 0 | C143: =SUMIF('KAPASİTE TABLOSU'!$F:$F,'İL-İLÇE BAZINDA KAPASİTE'!$A143,'KAPASİTE TABLOSU'!#REF!) -> #REF! | D143: =SUMIF('KAPASİTE TABLOSU'!$F:$F,'İL-İLÇE BAZINDA KAPASİTE'!$A143,'KAPASİTE TABLOSU'!#REF!) -> #REF! | E143: =SUMIF('KAPASİTE TABLOSU'!$F:$F,'İL-İLÇE BAZINDA KAPASİTE'!$A143,'KAPASİTE TABLOSU'!#REF!) -> #REF! | F143: =IF(G143=H143,"İL","İLÇE") -> İL | G143: KIRŞEHİR | H143: KIRŞEHİR
A144: KIRŞEHİR/KAMAN | B144: =COUNTIF('KAPASİTE TABLOSU'!F:F,'İL-İLÇE BAZINDA KAPASİTE'!A144) -> 0 | C144: =SUMIF('KAPASİTE TABLOSU'!$F:$F,'İL-İLÇE BAZINDA KAPASİTE'!$A144,'KAPASİTE TABLOSU'!#REF!) -> #REF! | D144: =SUMIF('KAPASİTE TABLOSU'!$F:$F,'İL-İLÇE BAZINDA KAPASİTE'!$A144,'KAPASİTE TABLOSU'!#REF!) -> #REF! | E144: =SUMIF('KAPASİTE TABLOSU'!$F:$F,'İL-İLÇE BAZINDA KAPASİTE'!$A144,'KAPASİTE TABLOSU'!#REF!) -> #REF! | F144: =IF(G144=H144,"İL","İLÇE") -> İLÇE | G144: KIRŞEHİR | H144: KAMAN
A145: KIRŞEHİR/MUCUR | B145: =COUNTIF('KAPASİTE TABLOSU'!F:F,'İL-İLÇE BAZINDA KAPASİTE'!A145) -> 0 | C145: =SUMIF('KAPASİTE TABLOSU'!$F:$F,'İL-İLÇE BAZINDA KAPASİTE'!$A145,'KAPASİTE TABLOSU'!#REF!) -> #REF! | D145: =SUMIF('KAPASİTE TABLOSU'!$F:$F,'İL-İLÇE BAZINDA KAPASİTE'!$A145,'KAPASİTE TABLOSU'!#REF!) -> #REF! | E145: =SUMIF('KAPASİTE TABLOSU'!$F:$F,'İL-İLÇE BAZINDA KAPASİTE'!$A145,'KAPASİTE TABLOSU'!#REF!) -> #REF! | F145: =IF(G145=H145,"İL","İLÇE") -> İLÇE | G145: KIRŞEHİR | H145: MUCUR
A146: KİLİS/KİLİS | B146: =COUNTIF('KAPASİTE TABLOSU'!F:F,'İL-İLÇE BAZINDA KAPASİTE'!A146) -> 0 | C146: =SUMIF('KAPASİTE TABLOSU'!$F:$F,'İL-İLÇE BAZINDA KAPASİTE'!$A146,'KAPASİTE TABLOSU'!#REF!) -> #REF! | D146: =SUMIF('KAPASİTE TABLOSU'!$F:$F,'İL-İLÇE BAZINDA KAPASİTE'!$A146,'KAPASİTE TABLOSU'!#REF!) -> #REF! | E146: =SUMIF('KAPASİTE TABLOSU'!$F:$F,'İL-İLÇE BAZINDA KAPASİTE'!$A146,'KAPASİTE TABLOSU'!#REF!) -> #REF! | F146: =IF(G146=H146,"İL","İLÇE") -> İL | G146: KİLİS | H146: KİLİS
... A263: ZONGULDAK/K.EREĞLİ | B263: =COUNTIF('KAPASİTE TABLOSU'!F:F,'İL-İLÇE BAZINDA KAPASİTE'!A263) -> 0 | C263: =SUMIF('KAPASİTE TABLOSU'!$F:$F,'İL-İLÇE BAZINDA KAPASİTE'!$A263,'KAPASİTE TABLOSU'!#REF!) -> #REF! | D263: =SUMIF('KAPASİTE TABLOSU'!$F:$F,'İL-İLÇE BAZINDA KAPASİTE'!$A263,'KAPASİTE TABLOSU'!#REF!) -> #REF! | E263: =SUMIF('KAPASİTE TABLOSU'!$F:$F,'İL-İLÇE BAZINDA KAPASİTE'!$A263,'KAPASİTE TABLOSU'!#REF!) -> #REF! | F263: =IF(G263=H263,"İL","İLÇE") -> İLÇE | G263: ZONGULDAK | H263: K.EREĞLİ
A264: KIBRIS/LEFKE | B264: =COUNTIF('KAPASİTE TABLOSU'!F:F,'İL-İLÇE BAZINDA KAPASİTE'!A264) -> 0 | C264: =SUMIF('KAPASİTE TABLOSU'!$F:$F,'İL-İLÇE BAZINDA KAPASİTE'!$A264,'KAPASİTE TABLOSU'!#REF!) -> #REF! | D264: =SUMIF('KAPASİTE TABLOSU'!$F:$F,'İL-İLÇE BAZINDA KAPASİTE'!$A264,'KAPASİTE TABLOSU'!#REF!) -> #REF! | E264: =SUMIF('KAPASİTE TABLOSU'!$F:$F,'İL-İLÇE BAZINDA KAPASİTE'!$A264,'KAPASİTE TABLOSU'!#REF!) -> #REF! | F264: KIBRIS | G264: KIBRIS | H264: LEFKE
A265: KIBRIS/MAGOSA | B265: =COUNTIF('KAPASİTE TABLOSU'!F:F,'İL-İLÇE BAZINDA KAPASİTE'!A265) -> 0 | C265: =SUMIF('KAPASİTE TABLOSU'!$F:$F,'İL-İLÇE BAZINDA KAPASİTE'!$A265,'KAPASİTE TABLOSU'!#REF!) -> #REF! | D265: =SUMIF('KAPASİTE TABLOSU'!$F:$F,'İL-İLÇE BAZINDA KAPASİTE'!$A265,'KAPASİTE TABLOSU'!#REF!) -> #REF! | E265: =SUMIF('KAPASİTE TABLOSU'!$F:$F,'İL-İLÇE BAZINDA KAPASİTE'!$A265,'KAPASİTE TABLOSU'!#REF!) -> #REF! | F265: KIBRIS | G265: KIBRIS | H265: MAGOSA
A266: TOPLAM | B266: =SUM(B3:B265) -> 1 | C266: =SUM(C3:C265) -> #REF! | D266: =SUM(D3:D265) -> #REF! | E266: =SUM(E3:E265) -> #REF!

Sheet YURT TİPİ
A1: İL | B1: YURT SAYISI | F1: KAPASİTE
B2: KIZ | C2: ERKEK | D2: AYRI | E2: TOPLAM | F2: KIZ | G2: ERKEK | H2: AYRI | I2: TOPLAM
A3: ADANA | B3: =COUNTIFS('KAPASİTE TABLOSU'!$A:$A,A3,'KAPASİTE TABLOSU'!$D:$D,"KIZ") -> 0 | C3: =COUNTIFS('KAPASİTE TABLOSU'!$A:$A,A3,'KAPASİTE TABLOSU'!$D:$D,"ERKEK") -> 0 | D3: =COUNTIFS('KAPASİTE TABLOSU'!$A:$A,A3,'KAPASİTE TABLOSU'!$D:$D,"AYRI") -> 0 | E3: =SUM(B3:D3) -> 0 | F3: =SUMIFS('KAPASİTE TABLOSU'!#REF!,'KAPASİTE TABLOSU'!$A:$A,A3,'KAPASİTE TABLOSU'!$D:$D,"KIZ") -> #REF! | G3: =SUMIFS('KAPASİTE TABLOSU'!#REF!,'KAPASİTE TABLOSU'!$A:$A,A3,'KAPASİTE TABLOSU'!$D:$D,"ERKEK") -> #REF! | H3: =SUMIFS('KAPASİTE TABLOSU'!#REF!,'KAPASİTE TABLOSU'!$A:$A,A3,'KAPASİTE TABLOSU'!$D:$D,"AYRI") -> #REF! | I3: =SUM(F3:H3) -> #REF!
A4: ADIYAMAN | B4: =COUNTIFS('KAPASİTE TABLOSU'!$A:$A,A4,'KAPASİTE TABLOSU'!$D:$D,"KIZ") -> 0 | C4: =COUNTIFS('KAPASİTE TABLOSU'!$A:$A,A4,'KAPASİTE TABLOSU'!$D:$D,"ERKEK") -> 0 | D4: =COUNTIFS('KAPASİTE TABLOSU'!$A:$A,A4,'KAPASİTE TABLOSU'!$D:$D,"AYRI") -> 0 | E4: =SUM(B4:D4) -> 0 | F4: =SUMIFS('KAPASİTE TABLOSU'!#REF!,'KAPASİTE TABLOSU'!$A:$A,A4,'KAPASİTE TABLOSU'!$D:$D,"KIZ") -> #REF! | G4: =SUMIFS('KAPASİTE TABLOSU'!#REF!,'KAPASİTE TABLOSU'!$A:$A,A4,'KAPASİTE TABLOSU'!$D:$D,"ERKEK") -> #REF! | H4: =SUMIFS('KAPASİTE TABLOSU'!#REF!,'KAPASİTE TABLOSU'!$A:$A,A4,'KAPASİTE TABLOSU'!$D:$D,"AYRI") -> #REF! | I4: =SUM(F4:H4) -> #REF!
A5: AFYONKARAHİSAR | B5: =COUNTIFS('KAPASİTE TABLOSU'!$A:$A,A5,'KAPASİTE TABLOSU'!$D:$D,"KIZ") -> 0 | C5: =COUNTIFS('KAPASİTE TABLOSU'!$A:$A,A5,'KAPASİTE TABLOSU'!$D:$D,"ERKEK") -> 0 | D5: =COUNTIFS('KAPASİTE TABLOSU'!$A:$A,A5,'KAPASİTE TABLOSU'!$D:$D,"AYRI") -> 0 | E5: =SUM(B5:D5) -> 0 | F5: =SUMIFS('KAPASİTE TABLOSU'!#REF!,'KAPASİTE TABLOSU'!$A:$A,A5,'KAPASİTE TABLOSU'!$D:$D,"KIZ") -> #REF! | G5: =SUMIFS('KAPASİTE TABLOSU'!#REF!,'KAPASİTE TABLOSU'!$A:$A,A5,'KAPASİTE TABLOSU'!$D:$D,"ERKEK") -> #REF! | H5: =SUMIFS('KAPASİTE TABLOSU'!#REF!,'KAPASİTE TABLOSU'!$A:$A,A5,'KAPASİTE TABLOSU'!$D:$D,"AYRI") -> #REF! | I5: =SUM(F5:H5) -> #REF!
A6: AĞRI | B6: =COUNTIFS('KAPASİTE TABLOSU'!$A:$A,A6,'KAPASİTE TABLOSU'!$D:$D,"KIZ") -> 0 | C6: =COUNTIFS('KAPASİTE TABLOSU'!$A:$A,A6,'KAPASİTE TABLOSU'!$D:$D,"ERKEK") -> 0 | D6: =COUNTIFS('KAPASİTE TABLOSU'!$A:$A,A6,'KAPASİTE TABLOSU'!$D:$D,"AYRI") -> 0 | E6: =SUM(B6:D6) -> 0 | F6: =SUMIFS('KAPASİTE TABLOSU'!#REF!,'KAPASİTE TABLOSU'!$A:$A,A6,'KAPASİTE TABLOSU'!$D:$D,"KIZ") -> #REF! | G6: =SUMIFS('KAPASİTE TABLOSU'!#REF!,'KAPASİTE TABLOSU'!$A:$A,A6,'KAPASİTE TABLOSU'!$D:$D,"ERKEK") -> #REF! | H6: =SUMIFS('KAPASİTE TABLOSU'!#REF!,'KAPASİTE TABLOSU'!$A:$A,A6,'KAPASİTE TABLOSU'!$D:$D,"AYRI") -> #REF! | I6: =SUM(F6:H6) -> #REF!
A7: AKSARAY | B7: =COUNTIFS('KAPASİTE TABLOSU'!$A:$A,A7,'KAPASİTE TABLOSU'!$D:$D,"KIZ") -> 0 | C7: =COUNTIFS('KAPASİTE TABLOSU'!$A:$A,A7,'KAPASİTE TABLOSU'!$D:$D,"ERKEK") -> 0 | D7: =COUNTIFS('KAPASİTE TABLOSU'!$A:$A,A7,'KAPASİTE TABLOSU'!$D:$D,"AYRI") -> 0 | E7: =SUM(B7:D7) -> 0 | F7: =SUMIFS('KAPASİTE TABLOSU'!#REF!,'KAPASİTE TABLOSU'!$A:$A,A7,'KAPASİTE TABLOSU'!$D:$D,"KIZ") -> #REF! | G7: =SUMIFS('KAPASİTE TABLOSU'!#REF!,'KAPASİTE TABLOSU'!$A:$A,A7,'KAPASİTE TABLOSU'!$D:$D,"ERKEK") -> #REF! | H7: =SUMIFS('KAPASİTE TABLOSU'!#REF!,'KAPASİTE TABLOSU'!$A:$A,A7,'KAPASİTE TABLOSU'!$D:$D,"AYRI") -> #REF! | I7: =SUM(F7:H7) -> #REF!
A8: AMASYA | B8: =COUNTIFS('KAPASİTE TABLOSU'!$A:$A,A8,'KAPASİTE TABLOSU'!$D:$D,"KIZ") -> 0 | C8: =COUNTIFS('KAPASİTE TABLOSU'!$A:$A,A8,'KAPASİTE TABLOSU'!$D:$D,"ERKEK") -> 0 | D8: =COUNTIFS('KAPASİTE TABLOSU'!$A:$A,A8,'KAPASİTE TABLOSU'!$D:$D,"AYRI") -> 0 | E8: =SUM(B8:D8) -> 0 | F8: =SUMIFS('KAPASİTE TABLOSU'!#REF!,'KAPASİTE TABLOSU'!$A:$A,A8,'KAPASİTE TABLOSU'!$D:$D,"KIZ") -> #REF! | G8: =SUMIFS('KAPASİTE TABLOSU'!#REF!,'KAPASİTE TABLOSU'!$A:$A,A8,'KAPASİTE TABLOSU'!$D:$D,"ERKEK") -> #REF! | H8: =SUMIFS('KAPASİTE TABLOSU'!#REF!,'KAPASİTE TABLOSU'!$A:$A,A8,'KAPASİTE TABLOSU'!$D:$D,"AYRI") -> #REF! | I8: =SUM(F8:H8) -> #REF!
A9: ANKARA | B9: =COUNTIFS('KAPASİTE TABLOSU'!$A:$A,A9,'KAPASİTE TABLOSU'!$D:$D,"KIZ") -> 0 | C9: =COUNTIFS('KAPASİTE TABLOSU'!$A:$A,A9,'KAPASİTE TABLOSU'!$D:$D,"ERKEK") -> 0 | D9: =COUNTIFS('KAPASİTE TABLOSU'!$A:$A,A9,'KAPASİTE TABLOSU'!$D:$D,"AYRI") -> 0 | E9: =SUM(B9:D9) -> 0 | F9: =SUMIFS('KAPASİTE TABLOSU'!#REF!,'KAPASİTE TABLOSU'!$A:$A,A9,'KAPASİTE TABLOSU'!$D:$D,"KIZ") -> #REF! | G9: =SUMIFS('KAPASİTE TABLOSU'!#REF!,'KAPASİTE TABLOSU'!$A:$A,A9,'KAPASİTE TABLOSU'!$D:$D,"ERKEK") -> #REF! | H9: =SUMIFS('KAPASİTE TABLOSU'!#REF!,'KAPASİTE TABLOSU'!$A:$A,A9,'KAPASİTE TABLOSU'!$D:$D,"AYRI") -> #REF! | I9: =SUM(F9:H9) -> #REF!
A10: ANTALYA | B10: =COUNTIFS('KAPASİTE TABLOSU'!$A:$A,A10,'KAPASİTE TABLOSU'!$D:$D,"KIZ") -> 0 | C10: =COUNTIFS('KAPASİTE TABLOSU'!$A:$A,A10,'KAPASİTE TABLOSU'!$D:$D,"ERKEK") -> 0 | D10: =COUNTIFS('KAPASİTE TABLOSU'!$A:$A,A10,'KAPASİTE TABLOSU'!$D:$D,"AYRI") -> 0 | E10: =SUM(B10:D10) -> 0 | F10: =SUMIFS('KAPASİTE TABLOSU'!#REF!,'KAPASİTE TABLOSU'!$A:$A,A10,'KAPASİTE TABLOSU'!$D:$D,"KIZ") -> #REF! | G10: =SUMIFS('KAPASİTE TABLOSU'!#REF!,'KAPASİTE TABLOSU'!$A:$A,A10,'KAPASİTE TABLOSU'!$D:$D,"ERKEK") -> #REF! | H10: =SUMIFS('KAPASİTE TABLOSU'!#REF!,'KAPASİTE TABLOSU'!$A:$A,A10,'KAPASİTE TABLOSU'!$D:$D,"AYRI") -> #REF! | I10: =SUM(F10:H10) -> #REF!
A11: ARDAHAN | B11: =COUNTIFS('KAPASİTE TABLOSU'!$A:$A,A11,'KAPASİTE TABLOSU'!$D:$D,"KIZ") -> 0 | C11: =COUNTIFS('KAPASİTE TABLOSU'!$A:$A,A11,'KAPASİTE TABLOSU'!$D:$D,"ERKEK") -> 0 | D11: =COUNTIFS('KAPASİTE TABLOSU'!$A:$A,A11,'KAPASİTE TABLOSU'!$D:$D,"AYRI") -> 0 | E11: =SUM(B11:D11) -> 0 | F11: =SUMIFS('KAPASİTE TABLOSU'!#REF!,'KAPASİTE TABLOSU'!$A:$A,A11,'KAPASİTE TABLOSU'!$D:$D,"KIZ") -> #REF! | G11: =SUMIFS('KAPASİTE TABLOSU'!#REF!,'KAPASİTE TABLOSU'!$A:$A,A11,'KAPASİTE TABLOSU'!$D:$D,"ERKEK") -> #REF! | H11: =SUMIFS('KAPASİTE TABLOSU'!#REF!,'KAPASİTE TABLOSU'!$A:$A,A11,'KAPASİTE TABLOSU'!$D:$D,"AYRI") -> #REF! | I11: =SUM(F11:H11) -> #REF!
A12: ARTVİN | B12: =COUNTIFS('KAPASİTE TABLOSU'!$A:$A,A12,'KAPASİTE TABLOSU'!$D:$D,"KIZ") -> 0 | C12: =COUNTIFS('KAPASİTE TABLOSU'!$A:$A,A12,'KAPASİTE TABLOSU'!$D:$D,"ERKEK") -> 0 | D12: =COUNTIFS('KAPASİTE TABLOSU'!$A:$A,A12,'KAPASİTE TABLOSU'!$D:$D,"AYRI") -> 0 | E12: =SUM(B12:D12) -> 0 | F12: =SUMIFS('KAPASİTE TABLOSU'!#REF!,'KAPASİTE TABLOSU'!$A:$A,A12,'KAPASİTE TABLOSU'!$D:$D,"KIZ") -> #REF! | G12: =SUMIFS('KAPASİTE TABLOSU'!#REF!,'KAPASİTE TABLOSU'!$A:$A,A12,'KAPASİTE TABLOSU'!$D:$D,"ERKEK") -> #REF! | H12: =SUMIFS('KAPASİTE TABLOSU'!#REF!,'KAPASİTE TABLOSU'!$A:$A,A12,'KAPASİTE TABLOSU'!$D:$D,"AYRI") -> #REF! | I12: =SUM(F12:H12) -> #REF!
A13: AYDIN | B13: =COUNTIFS('KAPASİTE TABLOSU'!$A:$A,A13,'KAPASİTE TABLOSU'!$D:$D,"KIZ") -> 0 | C13: =COUNTIFS('KAPASİTE TABLOSU'!$A:$A,A13,'KAPASİTE TABLOSU'!$D:$D,"ERKEK") -> 0 | D13: =COUNTIFS('KAPASİTE TABLOSU'!$A:$A,A13,'KAPASİTE TABLOSU'!$D:$D,"AYRI") -> 0 | E13: =SUM(B13:D13) -> 0 | F13: =SUMIFS('KAPASİTE TABLOSU'!#REF!,'KAPASİTE TABLOSU'!$A:$A,A13,'KAPASİTE TABLOSU'!$D:$D,"KIZ") -> #REF! | G13: =SUMIFS('KAPASİTE TABLOSU'!#REF!,'KAPASİTE TABLOSU'!$A:$A,A13,'KAPASİTE TABLOSU'!$D:$D,"ERKEK") -> #REF! | H13: =SUMIFS('KAPASİTE TABLOSU'!#REF!,'KAPASİTE TABLOSU'!$A:$A,A13,'KAPASİTE TABLOSU'!$D:$D,"AYRI") -> #REF! | I13: =SUM(F13:H13) -> #REF!
A14: BALIKESİR | B14: =COUNTIFS('KAPASİTE TABLOSU'!$A:$A,A14,'KAPASİTE TABLOSU'!$D:$D,"KIZ") -> 0 | C14: =COUNTIFS('KAPASİTE TABLOSU'!$A:$A,A14,'KAPASİTE TABLOSU'!$D:$D,"ERKEK") -> 0 | D14: =COUNTIFS('KAPASİTE TABLOSU'!$A:$A,A14,'KAPASİTE TABLOSU'!$D:$D,"AYRI") -> 0 | E14: =SUM(B14:D14) -> 0 | F14: =SUMIFS('KAPASİTE TABLOSU'!#REF!,'KAPASİTE TABLOSU'!$A:$A,A14,'KAPASİTE TABLOSU'!$D:$D,"KIZ") -> #REF! | G14: =SUMIFS('KAPASİTE TABLOSU'!#REF!,'KAPASİTE TABLOSU'!$A:$A,A14,'KAPASİTE TABLOSU'!$D:$D,"ERKEK") -> #REF! | H14: =SUMIFS('KAPASİTE TABLOSU'!#REF!,'KAPASİTE TABLOSU'!$A:$A,A14,'KAPASİTE TABLOSU'!$D:$D,"AYRI") -> #REF! | I14: =SUM(F14:H14) -> #REF!
... A84: KIBRIS | B84: =COUNTIFS('KAPASİTE TABLOSU'!$A:$A,A84,'KAPASİTE TABLOSU'!$D:$D,"KIZ") -> 0 | C84: =COUNTIFS('KAPASİTE TABLOSU'!$A:$A,A84,'KAPASİTE TABLOSU'!$D:$D,"ERKEK") -> 0 | D84: =COUNTIFS('KAPASİTE TABLOSU'!$A:$A,A84,'KAPASİTE TABLOSU'!$D:$D,"AYRI") -> 0 | E84: =SUM(B84:D84) -> 0 | F84: =SUMIFS('KAPASİTE TABLOSU'!#REF!,'KAPASİTE TABLOSU'!$A:$A,A84,'KAPASİTE TABLOSU'!$D:$D,"KIZ") -> #REF! | G84: =SUMIFS('KAPASİTE TABLOSU'!#REF!,'KAPASİTE TABLOSU'!$A:$A,A84,'KAPASİTE TABLOSU'!$D:$D,"ERKEK") -> #REF! | H84: =SUMIFS('KAPASİTE TABLOSU'!#REF!,'KAPASİTE TABLOSU'!$A:$A,A84,'KAPASİTE TABLOSU'!$D:$D,"AYRI") -> #REF! | I84: =SUM(F84:H84) -> #REF!
A85: TOPLAM | B85: =SUM(B3:B84) -> 0 | C85: =SUM(C3:C84) -> 0 | D85: =SUM(D3:D84) -> 0 | E85: =SUM(E3:E84) -> 0 | F85: =SUM(F3:F84) -> #REF! | G85: =SUM(G3:G84) -> #REF! | H85: =SUM(H3:H84) -> #REF! | I85: =SUM(I3:I84) -> #REF!
